Workbook

Sheet Sheet1
A1: Order ID | B1: Order Date | C1: Customer Name | D1: Country | E1: City | F1: Product Category | G1: Product Name | H1: Quantity | I1: Unit Price | J1: Discount | K1: Total Sales | L1: Payment Method | M1: Order Status | N1: Delivery Date | O1: Customer Rating
A2: ORD1001 | B2: 45798 | C2: Peter Johnson | D2: NIGERIA | E2: Lagos | F2: Electronics | G2: ELEC-1002-Y-Bluetooth Speaker | H2: 3 | I2: 370.87 | J2: 20 | K2: 890.09 | L2: Credit Card | M2: delivered | N2: 45802 | O2: 1
A3: ORD1002 | B3: 45945 | C3: Daniel Anderson | D3: UK | E3: London | F3: Beauty | G3: BEAU-4001-C-Face Serum | H3: 7 | I3: 118.02 | J3: 20 | K3: 660.91 | L3: creditcard | M3: Shipped | N3: 45949 | O3: 3
A4: ORD1003 | B4: 45768 | C4: Aisha Garcia | D4: Ghana | E4: Accra | F4: Electronic | G4: HOME-2001-A-Air Fryer | H4: 2 | I4: 55.45 | J4: 0 | K4: 110.9 | L4: Credit Card | M4: Shipped | N4: 45781 | O4: 3
A5: ORD1004 | B5: 45698 | C5: Daniel Johnson | D5: South Africa | E5: Cape Town | F5: Electronics | G5: HOME-2001-A-Air Fryer | H5: 10 | I5: 443.87 | J5: 10 | K5: 3994.83 | L5: Credit Card | M5: Shipped | N5: 45707 | O5: 5
A6: ORD1005 | B6: 45777 | C6: Ahmed Garcia | D6: nigeria | E6: Kano | F6: electronics | G6: ELEC-1001-X-Wireless Mouse | H6: 7 | I6: 146.21 | J6: 10 | K6: 921.12 | L6: Cash | M6: Complete | N6: 45791 | O6: 2
A7: ORD1006 | B7: 45931 | C7: Grace Thomas | D7: Kenya | E7: Nairobi | F7: Electronic | G7: ELEC-1002-Y-Bluetooth Speaker | H7: 3 | I7: 236.51 | J7: 10 | K7: 638.58 | L7: Credit Card | M7: delivered | N7: 45943 | O7: 5
A8: ORD1007 | B8: 45795 | C8: Ahmed Rauf | D8: United Kingdom | E8: London | F8: fashion | G8: ELEC-1002-Y-Bluetooth Speaker | H8: 10 | I8: 439.42 | J8: 10 | K8: 3954.78 | L8: PayPal | M8: delivered | N8: 45797 | O8: 2
A9: ORD1008 | B9: 45933 | C9: David Wilson | D9: Kenya | E9: Nairobi | F9: Fashion | G9: BEAU-4001-C-Face Serum | H9: 7 | I9: 449.93 | J9: 15 | K9: 2677.08 | L9: PayPal | M9: Delivered | N9: 45938 | O9: 3
A10: ORD1009 | B10: 45979 | C10: Sophia Johnson | D10: United Kingdom | E10: London | F10: Electronic | G10: FASH-3001-B-Running Shoes | H10: 10 | I10: 41.13 | J10: 15 | K10: 349.61 | L10: Bank Transfer | M10: Delivered | N10: 45982 | O10: 5
A11: ORD1010 | B11: 25/11/2025 | C11: Peter Taylor | D11: Ghana | E11: Accra | F11: Beauty | G11: ELEC-1001-X-Wireless Mouse | H11: 5 | I11: 223.03 | J11: 15 | K11: 947.88 | L11: creditcard | M11: Cancelled | N11: 45992 | O11: 1
A12: ORD1011 | B12: 45985 | C12: Sophia Thomas | D12: Nigeria | E12: Kano | F12: Electronic | G12: BEAU-4001-C-Face Serum | H12: 4 | I12: 84.89 | J12: 5 | K12: 322.58 | L12: PayPal | M12: Delivered | N12: 45994 | O12: 5
A13: ORD1012 | B13: 45780 | C13: Samuel Rauf | D13: United Kingdom | E13: London | F13: Fashion | G13: ELEC-1002-Y-Bluetooth Speaker | H13: 10 | I13: 474.01 | J13: 0 | K13: 4740.1 | L13: creditcard | M13: delivered | N13: 45781 | O13: 4
A14: ORD1013 | B14: 45928 | C14: Daniel Brown | D14: Kenya | E14: Nairobi | F14: fashion | G14: BEAU-4001-C-Face Serum | H14: 7 | I14: 482.54 | J14: 20 | K14: 2702.22 | L14: Cash | M14: Complete | N14: 45942 | O14: 2
A15: ORD1014 | B15: 45719 | C15: Samuel Taylor | D15: Ghana | E15: Accra | F15: electronics | G15: ELEC-1002-Y-Bluetooth Speaker | H15: 2 | I15: 175.66 | J15: 20 | K15: 281.06 | L15: Credit Card | M15: Delivered | N15: 45723 | O15: 5
A16: ORD1014 | B16: 45719 | C16: Samuel Taylor | D16: Ghana | E16: Accra | F16: electronics | G16: ELEC-1002-Y-Bluetooth Speaker | H16: 2 | I16: 175.66 | J16: 20 | K16: 281.06 | L16: Credit Card | M16: Delivered | N16: 45723 | O16: 5
A17: ORD1015 | B17: 45827 | C17: Sarah Johnson | D17: NIGERIA | E17: Lagos | F17: Fashion | G17: BEAU-4001-C-Face Serum | H17: 4 | I17: 146.45 | J17: 15 | K17: 497.93 | L17: Bank Transfer | M17: Pending | N17: 45829 | O17: 2
A18: ORD1016 | B18: 45755 | C18: Ahmed Davis | D18: Nigeria | E18: Lagos | F18: fashion | G18: ELEC-1001-X-Wireless Mouse | H18: 7 | I18: 183.61 | J18: 15 | K18: 1092.48 | L18: Cash | M18: Delivered | N18: 45757 | O18: 4
A19: ORD1017 | B19: 45713 | C19: James Martin | D19: NIGERIA | E19: Kano | F19: Home & Kitchen | G19: ELEC-1002-Y-Bluetooth Speaker | H19: 4 | I19: 272.78 | J19: 5 | K19: 1036.56 | L19: creditcard | M19: Delivered | N19: 45717 | O19: 4
A20: ORD1018 | B20: 45683 | C20: Ahmed Taylor | D20: UK | E20: London | F20: Home & Kitchen | G20: BEAU-4001-C-Face Serum | H20: -2 | I20: 484.81 | J20: 5 | K20: -921.14 | L20: creditcard | M20: Pending | N20: 45694 | O20: 2
A21: ORD1019 | B21: 45857 | C21: David Miller | D21: NIGERIA | E21: Abuja | F21: Electronic | G21: FASH-3001-B-Running Shoes | H21: 5 | I21: 217.27 | J21: 20 | K21: 869.08 | L21: creditcard | M21: Delivered | N21: 45862 | O21: 4
A22: ORD1020 | B22: 45936 | C22: Linda Taylor | D22: Ghana | E22: Accra | F22: Electronics | G22: ELEC-1001-X-Wireless Mouse | H22: 10 | I22: 243.63 | J22: 20 | K22: 1949.04 | L22: creditcard | M22: Delivered | N22: 45819
A23: ORD1021 | B23: 45864 | C23: Mary Thomas | D23: kenya | E23: Nairobi | F23: fashion | G23: BEAU-4001-C-Face Serum | H23: 4 | I23: 293.67 | J23: 0 | K23: 1174.68 | L23: Bank Transfer | M23: Cancelled | N23: 45866 | O23: 5
A24: ORD1022 | B24: 46000 | C24: Aisha Garcia | D24: United Kingdom | E24: London | F24: Beauty | G24: HOME-2001-A-Air Fryer | H24: 4 | I24: 140.15 | J24: 150 | K24: -280.3 | L24: Credit Card | M24: Delivered | N24: 46012 | O24: 3
A25: ORD1023 | B25: 45695 | C25: grace anderson | D25: niGERIA | E25: Kano | F25: Electronic | G25: ELEC-1002-Y-Bluetooth Speaker | H25: 9 | I25: 139.95 | J25: 10 | K25: 1133.6 | L25: creditcard | M25: Pending | N25: 45704 | O25: 1
A26: ORD1024 | B26: 45992 | C26: Linda Garcia | D26: Ghana | E26: Accra | F26: Electronics | G26: ELEC-1001-X-Wireless Mouse | H26: 9 | I26: 156.7 | J26: 0 | K26: 1410.3 | L26: Cash | M26: Cancelled | N26: 46001 | O26: 8
A27: ORD1025 | B27: 45765 | C27: Michael Garcia | D27: United Kingdom | E27: London | F27: Beauty | G27: HOME-2001-A-Air Fryer | H27: 4 | I27: 346.87 | J27: 10 | K27: 1248.73 | L27: Credit Card | M27: Delivered | N27: 45762 | O27: 5
A28: ORD1026 | B28: 45658 | C28: Sophia Garcia | D28: UK | E28: London | F28: Electronics | G28: ELEC-1002-Y-Bluetooth Speaker | H28: 0 | I28: 89.18 | J28: 15 | K28: 0 | L28: Credit Card | M28: Delivered | N28: 45665 | O28: 5
A29: ORD1027 | B29: 45956 | C29: Daniel Smith | D29: Nigeria | E29: Kano | F29: electronics | G29: ELEC-1002-Y-Bluetooth Speaker | H29: 7 | I29: 72.45 | J29: 10 | K29: 456.44 | L29: Cash | M29: delivered | O29: 3
A30: ORD1028 | B30: 45975 | D30: Nigeria | E30: Abuja | F30: fashion | G30: ELEC-1002-Y-Bluetooth Speaker | H30: 4 | I30: 433.66 | J30: 5 | K30: 1647.91 | L30: Credit-card | M30: Pending | N30: 45987 | O30: 4
A31: ORD1006 | B31: 45931 | C31: Grace Thomas | D31: South Africa | E31: Cape Town | F31: Electronic | G31: ELEC-1002-Y-Bluetooth Speaker | H31: 3 | I31: 236.51 | J31: 10 | K31: 638.58 | L31: Credit Card | M31: delivered | N31: 45943 | O31: 5
A32: ORD1029 | B32: 45853 | C32: MICHAEL BROWN | D32: Ghana | E32: Accra | F32: Beauty | G32: ELEC-1001-X-Wireless Mouse | H32: 8 | I32: 118.99 | J32: 15 | K32: 809.13 | L32: creditcard | M32: delivered | N32: 45867 | O32: 3
A33: ORD1030 | B33: 18/06/2025 | C33: Peter Wilson | D33: South Africa | E33: Cape Town | F33: Electronics | G33: ELEC-1001-X-Wireless Mouse | H33: 5 | I33: 182.06 | J33: 20 | K33: 728.24 | L33: Credit-card | M33: delivered | N33: 45831 | O33: 4
A34: ORD1031 | B34: 45963 | C34: Michael Smith | D34: Ghana | E34: Accra | F34: electronics | G34: HOME-2001-A-Air Fryer | H34: 6 | I34: 223.83 | J34: 20 | K34: 1074.38 | L34: Credit-card | M34: Delivered | N34: 45970 | O34: 1
A35: ORD1032 | B35: 46009 | C35: John Taylor | D35: South Africa | E35: Cape Town | F35: Beauty | G35: ELEC-1002-Y-Bluetooth Speaker | H35: 6 | I35: 221.34 | J35: 10 | K35: 1195.24 | L35: Credit Card | M35: Shipped | N35: 46021 | O35: 5
A36: ORD1033 | B36: 45658 | C36: Daniel Garcia | D36: UK | E36: London | F36: fashion | G36: FASH-3001-B-Running Shoes | H36: 5 | I36: 281.66 | J36: 5 | K36: 1337.89 | L36: creditcard | M36: Cancelled | N36: 45873 | O36: 4
A37: ORD1034 | B37: 45658 | C37: Michael Miller | D37: Kenya | E37: Nairobi | F37: Home & Kitchen | G37: HOME-2001-A-Air Fryer | H37: 4 | I37: 220.65 | J37: 20 | K37: 706.08 | L37: PayPal | M37: Shipped | N37: 45663 | O37: 5
A38: ORD1035 | B38: 45995 | C38: Daniel Davis | D38: nigeria | E38: Lagos | F38: Beauty | G38: HOME-2001-A-Air Fryer | H38: 9 | I38: 335.29 | J38: 20 | K38: 2414.09 | L38: creditcard | M38: Shipped | N38: 45997 | O38: 3
A39: ORD1036 | B39: 45670 | C39: Sarah Wilson | D39: UK | E39: London | F39: Fashion | G39: ELEC-1002-Y-Bluetooth Speaker | H39: -2 | I39: 309.52 | J39: 0 | K39: -619.04 | L39: creditcard | M39: Shipped | N39: 45671 | O39: 4
A40: ORD1037 | B40: 45733 | C40: Fatima Miller | D40: United Kingdom | E40: London | F40: Fashion | G40: ELEC-1001-X-Wireless Mouse | H40: 2 | I40: 391.43 | J40: 5 | K40: 743.72 | L40: creditcard | M40: Delivered | N40: 45744 | O40: 2
...

Sheet Cleaned 
A1: Order ID | B1: Order Date | C1: Customer Name | D1: Country | E1: City | F1: Original Product Category | G1: Product Name | H1: Category Code | I1: Cleaned Product Category | J1: Category Match | K1: Quantity | L1: Unit Price | M1: Discount | N1: Total Sales | O1: Payment Method | P1: Order Status | Q1: Delivery Date | R1: Customer Rating | S1: Order date <= Delivery Date
A2: ORD1001 | B2: 45798 | C2: Peter Johnson | D2: Nigeria | E2: Lagos | F2: Electronics | G2: ELEC-1002-Y-Bluetooth Speaker | H2: ELEC | I2: =VLOOKUP(H2,REPORT!$B$1:$C$4,2,FALSE) -> Electronics | J2: =IF(F2=I2,"Match","Mismatch") -> Match | K2: 3 | L2: 370.87 | M2: 0.2 | N2: 890.09 | O2: Credit Card | P2: Delivered | Q2: 45802 | R2: 1 | S2: =IF(B2<=Q2,"YES","NO") -> YES
A3: ORD1002 | B3: 45945 | C3: Daniel Anderson | D3: United Kingdom | E3: London | F3: Beauty | G3: BEAU-4001-C-Face Serum | H3: BEAU | I3: =VLOOKUP(H3,REPORT!$B$1:$C$4,2,FALSE) -> Beauty | J3: =IF(F3=I3,"Match","Mismatch") -> Match | K3: 7 | L3: 118.02 | M3: 0.2 | N3: 660.91 | O3: Credit Card | P3: Shipped | Q3: 45949 | R3: 3 | S3: =IF(B3<=Q3,"YES","NO") -> YES
A4: ORD1003 | B4: 45768 | C4: Aisha Garcia | D4: Ghana | E4: Accra | F4: Electronics | G4: HOME-2001-A-Air Fryer | H4: HOME | I4: =VLOOKUP(H4,REPORT!$B$1:$C$4,2,FALSE) -> Home & Kitchen | J4: =IF(F4=I4,"Match","Mismatch") -> Mismatch | K4: 2 | L4: 55.45 | M4: 0 | N4: 110.9 | O4: Credit Card | P4: Shipped | Q4: 45781 | R4: 3 | S4: =IF(B4<=Q4,"YES","NO") -> YES
A5: ORD1004 | B5: 45932 | C5: Daniel Johnson | D5: South Africa | E5: Cape Town | F5: Electronics | G5: HOME-2001-A-Air Fryer | H5: HOME | I5: =VLOOKUP(H5,REPORT!$B$1:$C$4,2,FALSE) -> Home & Kitchen | J5: =IF(F5=I5,"Match","Mismatch") -> Mismatch | K5: 10 | L5: 443.87 | M5: 0.1 | N5: 3994.83 | O5: Credit Card | P5: Shipped | Q5: 45707 | R5: 5 | S5: =IF(B5<=Q5,"YES","NO") -> NO
A6: ORD1005 | B6: 45777 | C6: Ahmed Garcia | D6: Nigeria | E6: Kano | F6: Electronics | G6: ELEC-1001-X-Wireless Mouse | H6: ELEC | I6: =VLOOKUP(H6,REPORT!$B$1:$C$4,2,FALSE) -> Electronics | J6: =IF(F6=I6,"Match","Mismatch") -> Match | K6: 7 | L6: 146.21 | M6: 0.1 | N6: 921.12 | O6: Cash | P6: Complete | Q6: 45791 | R6: 2 | S6: =IF(B6<=Q6,"YES","NO") -> YES
A7: ORD1006 | B7: 45667 | C7: Grace Thomas | D7: Kenya | E7: Nairobi | F7: Electronics | G7: ELEC-1002-Y-Bluetooth Speaker | H7: ELEC | I7: =VLOOKUP(H7,REPORT!$B$1:$C$4,2,FALSE) -> Electronics | J7: =IF(F7=I7,"Match","Mismatch") -> Match | K7: 3 | L7: 236.51 | M7: 0.1 | N7: 638.58 | O7: Credit Card | P7: Delivered | Q7: 45943 | R7: 5 | S7: =IF(B7<=Q7,"YES","NO") -> YES
A8: ORD1007 | B8: 45795 | C8: Ahmed Rauf | D8: United Kingdom | E8: London | F8: Fashion | G8: ELEC-1002-Y-Bluetooth Speaker | H8: ELEC | I8: =VLOOKUP(H8,REPORT!$B$1:$C$4,2,FALSE) -> Electronics | J8: =IF(F8=I8,"Match","Mismatch") -> Mismatch | K8: 10 | L8: 439.42 | M8: 0.1 | N8: 3954.78 | O8: PayPal | P8: Delivered | Q8: 45797 | R8: 2 | S8: =IF(B8<=Q8,"YES","NO") -> YES
A9: ORD1008 | B9: 45726 | C9: David Wilson | D9: Kenya | E9: Nairobi | F9: Fashion | G9: BEAU-4001-C-Face Serum | H9: BEAU | I9: =VLOOKUP(H9,REPORT!$B$1:$C$4,2,FALSE) -> Beauty | J9: =IF(F9=I9,"Match","Mismatch") -> Mismatch | K9: 7 | L9: 449.93 | M9: 0.15 | N9: 2677.08 | O9: PayPal | P9: Delivered | Q9: 45938 | R9: 3 | S9: =IF(B9<=Q9,"YES","NO") -> YES
A10: ORD1009 | B10: 45979 | C10: Sophia Johnson | D10: United Kingdom | E10: London | F10: Electronics | G10: FASH-3001-B-Running Shoes | H10: FASH | I10: =VLOOKUP(H10,REPORT!$B$1:$C$4,2,FALSE) -> Fashion | J10: =IF(F10=I10,"Match","Mismatch") -> Mismatch | K10: 10 | L10: 41.13 | M10: 0.15 | N10: 349.61 | O10: Bank Transfer | P10: Delivered | Q10: 45982 | R10: 5 | S10: =IF(B10<=Q10,"YES","NO") -> YES
A11: ORD1010 | B11: 45986 | C11: Peter Taylor | D11: Ghana | E11: Accra | F11: Beauty | G11: ELEC-1001-X-Wireless Mouse | H11: ELEC | I11: =VLOOKUP(H11,REPORT!$B$1:$C$4,2,FALSE) -> Electronics | J11: =IF(F11=I11,"Match","Mismatch") -> Mismatch | K11: 5 | L11: 223.03 | M11: 0.15 | N11: 947.88 | O11: Credit Card | P11: Cancelled | Q11: 45992 | R11: 1 | S11: =IF(B11<=Q11,"YES","NO") -> YES
A12: ORD1011 | B12: 45985 | C12: Sophia Thomas | D12: Nigeria | E12: Kano | F12: Electronics | G12: BEAU-4001-C-Face Serum | H12: BEAU | I12: =VLOOKUP(H12,REPORT!$B$1:$C$4,2,FALSE) -> Beauty | J12: =IF(F12=I12,"Match","Mismatch") -> Mismatch | K12: 4 | L12: 84.89 | M12: 0.05 | N12: 322.58 | O12: PayPal | P12: Delivered | Q12: 45994 | R12: 5 | S12: =IF(B12<=Q12,"YES","NO") -> YES
A13: ORD1012 | B13: 45721 | C13: Samuel Rauf | D13: United Kingdom | E13: London | F13: Fashion | G13: ELEC-1002-Y-Bluetooth Speaker | H13: ELEC | I13: =VLOOKUP(H13,REPORT!$B$1:$C$4,2,FALSE) -> Electronics | J13: =IF(F13=I13,"Match","Mismatch") -> Mismatch | K13: 10 | L13: 474.01 | M13: 0 | N13: 4740.1 | O13: Credit Card | P13: Delivered | Q13: 45781 | R13: 4 | S13: =IF(B13<=Q13,"YES","NO") -> YES
... A20: ORD1019 | B20: 45857 | C20: David Miller | D20: Nigeria | E20: Abuja | F20: Electronics | G20: FASH-3001-B-Running Shoes | H20: FASH | I20: =VLOOKUP(H20,REPORT!$B$1:$C$4,2,FALSE) -> Fashion | J20: =IF(F20=I20,"Match","Mismatch") -> Mismatch | K20: 5 | L20: 217.27 | M20: 0.2 | N20: 869.08 | O20: Credit Card | P20: Delivered | Q20: 45862 | R20: 4 | S20: =IF(B20<=Q20,"YES","NO") -> YES
A21: ORD1020 | B21: 45818 | C21: Linda Taylor | D21: Ghana | E21: Accra | F21: Electronics | G21: ELEC-1001-X-Wireless Mouse | H21: ELEC | I21: =VLOOKUP(H21,REPORT!$B$1:$C$4,2,FALSE) -> Electronics | J21: =IF(F21=I21,"Match","Mismatch") -> Match | K21: 10 | L21: 243.63 | M21: 0.2 | N21: 1949.04 | O21: Credit Card | P21: Delivered | Q21: 45819 | S21: =IF(B21<=Q21,"YES","NO") -> YES
A22: ORD1021 | B22: 45864 | C22: Mary Thomas | D22: Kenya | E22: Nairobi | F22: Fashion | G22: BEAU-4001-C-Face Serum | H22: BEAU | I22: =VLOOKUP(H22,REPORT!$B$1:$C$4,2,FALSE) -> Beauty | J22: =IF(F22=I22,"Match","Mismatch") -> Mismatch | K22: 4 | L22: 293.67 | M22: 0 | N22: 1174.68 | O22: Bank Transfer | P22: Cancelled | Q22: 45866 | R22: 5 | S22: =IF(B22<=Q22,"YES","NO") -> YES
A23: ORD1022 | B23: 45912 | C23: Aisha Garcia | D23: United Kingdom | E23: London | F23: Beauty | G23: HOME-2001-A-Air Fryer | H23: HOME | I23: =VLOOKUP(H23,REPORT!$B$1:$C$4,2,FALSE) -> Home & Kitchen | J23: =IF(F23=I23,"Match","Mismatch") -> Mismatch | K23: 4 | L23: 140.15 | M23: 1.5 | N23: -280.3 | O23: Credit Card | P23: Delivered | Q23: 46012 | R23: 3 | S23: =IF(B23<=Q23,"YES","NO") -> YES
A24: ORD1023 | B24: 45840 | C24: Grace Anderson | D24: Nigeria | E24: Kano | F24: Electronics | G24: ELEC-1002-Y-Bluetooth Speaker | H24: ELEC | I24: =VLOOKUP(H24,REPORT!$B$1:$C$4,2,FALSE) -> Electronics | J24: =IF(F24=I24,"Match","Mismatch") -> Match | K24: 9 | L24: 139.95 | M24: 0.1 | N24: 1133.6 | O24: Credit Card | P24: Pending | Q24: 45704 | R24: 1 | S24: =IF(B24<=Q24,"YES","NO") -> NO
A25: ORD1024 | B25: 45669 | C25: Linda Garcia | D25: Ghana | E25: Accra | F25: Electronics | G25: ELEC-1001-X-Wireless Mouse | H25: ELEC | I25: =VLOOKUP(H25,REPORT!$B$1:$C$4,2,FALSE) -> Electronics | J25: =IF(F25=I25,"Match","Mismatch") -> Match | K25: 9 | L25: 156.7 | M25: 0 | N25: 1410.3 | O25: Cash | P25: Cancelled | Q25: 46001 | R25: 8 | S25: =IF(B25<=Q25,"YES","NO") -> YES
A26: ORD1025 | B26: 45765 | C26: Michael Garcia | D26: United Kingdom | E26: London | F26: Beauty | G26: HOME-2001-A-Air Fryer | H26: HOME | I26: =VLOOKUP(H26,REPORT!$B$1:$C$4,2,FALSE) -> Home & Kitchen | J26: =IF(F26=I26,"Match","Mismatch") -> Mismatch | K26: 4 | L26: 346.87 | M26: 0.1 | N26: 1248.73 | O26: Credit Card | P26: Delivered | Q26: 45762 | R26: 5 | S26: =IF(B26<=Q26,"YES","NO") -> NO
A27: ORD1026 | B27: 45658 | C27: Sophia Garcia | D27: United Kingdom | E27: London | F27: Electronics | G27: ELEC-1002-Y-Bluetooth Speaker | H27: ELEC | I27: =VLOOKUP(H27,REPORT!$B$1:$C$4,2,FALSE) -> Electronics | J27: =IF(F27=I27,"Match","Mismatch") -> Match | K27: 0 | L27: 89.18 | M27: 0.15 | N27: 0 | O27: Credit Card | P27: Delivered | Q27: 45665 | R27: 5 | S27: =IF(B27<=Q27,"YES","NO") -> YES
A28: ORD1027 | B28: 45956 | C28: Daniel Smith | D28: Nigeria | E28: Kano | F28: Electronics | G28: ELEC-1002-Y-Bluetooth Speaker | H28: ELEC | I28: =VLOOKUP(H28,REPORT!$B$1:$C$4,2,FALSE) -> Electronics | J28: =IF(F28=I28,"Match","Mismatch") -> Match | K28: 7 | L28: 72.45 | M28: 0.1 | N28: 456.44 | O28: Cash | P28: Delivered | R28: 3 | S28: =IF(B28<=Q28,"YES","NO") -> NO
A29: ORD1028 | B29: 45975 | D29: Nigeria | E29: Abuja | F29: Fashion | G29: ELEC-1002-Y-Bluetooth Speaker | H29: ELEC | I29: =VLOOKUP(H29,REPORT!$B$1:$C$4,2,FALSE) -> Electronics | J29: =IF(F29=I29,"Match","Mismatch") -> Mismatch | K29: 4 | L29: 433.66 | M29: 0.05 | N29: 1647.91 | O29: Credit Card | P29: Pending | Q29: 45987 | R29: 4 | S29: =IF(B29<=Q29,"YES","NO") -> YES
A30: ORD1006 | B30: 45667 | C30: Grace Thomas | D30: South Africa | E30: Cape Town | F30: Electronics | G30: ELEC-1002-Y-Bluetooth Speaker | H30: ELEC | I30: =VLOOKUP(H30,REPORT!$B$1:$C$4,2,FALSE) -> Electronics | J30: =IF(F30=I30,"Match","Mismatch") -> Match | K30: 3 | L30: 236.51 | M30: 0.1 | N30: 638.58 | O30: Credit Card | P30: Delivered | Q30: 45943 | R30: 5 | S30: =IF(B30<=Q30,"YES","NO") -> YES
A31: ORD1029 | B31: 45853 | C31: Michael Brown | D31: Ghana | E31: Accra | F31: Beauty | G31: ELEC-1001-X-Wireless Mouse | H31: ELEC | I31: =VLOOKUP(H31,REPORT!$B$1:$C$4,2,FALSE) -> Electronics | J31: =IF(F31=I31,"Match","Mismatch") -> Mismatch | K31: 8 | L31: 118.99 | M31: 0.15 | N31: 809.13 | O31: Credit Card | P31: Delivered | Q31: 45867 | R31: 3 | S31: =IF(B31<=Q31,"YES","NO") -> YES
A32: ORD1030 | B32: 45826 | C32: Peter Wilson | D32: South Africa | E32: Cape Town | F32: Electronics | G32: ELEC-1001-X-Wireless Mouse | H32: ELEC | I32: =VLOOKUP(H32,REPORT!$B$1:$C$4,2,FALSE) -> Electronics | J32: =IF(F32=I32,"Match","Mismatch") -> Match | K32: 5 | L32: 182.06 | M32: 0.2 | N32: 728.24 | O32: Credit Card | P32: Delivered | Q32: 45831 | R32: 4 | S32: =IF(B32<=Q32,"YES","NO") -> YES
A33: ORD1031 | B33: 45699 | C33: Michael Smith | D33: Ghana | E33: Accra | F33: Electronics | G33: HOME-2001-A-Air Fryer | H33: HOME | I33: =VLOOKUP(H33,REPORT!$B$1:$C$4,2,FALSE) -> Home & Kitchen | J33: =IF(F33=I33,"Match","Mismatch") -> Mismatch | K33: 6 | L33: 223.83 | M33: 0.2 | N33: 1074.38 | O33: Credit Card | P33: Delivered | Q33: 45970 | R33: 1 | S33: =IF(B33<=Q33,"YES","NO") -> YES
A34: ORD1032 | B34: 46009 | C34: John Taylor | D34: South Africa | E34: Cape Town | F34: Beauty | G34: ELEC-1002-Y-Bluetooth Speaker | H34: ELEC | I34: =VLOOKUP(H34,REPORT!$B$1:$C$4,2,FALSE) -> Electronics | J34: =IF(F34=I34,"Match","Mismatch") -> Mismatch | K34: 6 | L34: 221.34 | M34: 0.1 | N34: 1195.24 | O34: Credit Card | P34: Shipped | Q34: 46021 | R34: 5 | S34: =IF(B34<=Q34,"YES","NO") -> YES
A35: ORD1033 | B35: 45658 | C35: Daniel Garcia | D35: United Kingdom | E35: London | F35: Fashion | G35: FASH-3001-B-Running Shoes | H35: FASH | I35: =VLOOKUP(H35,REPORT!$B$1:$C$4,2,FALSE) -> Fashion | J35: =IF(F35=I35,"Match","Mismatch") -> Match | K35: 5 | L35: 281.66 | M35: 0.05 | N35: 1337.89 | O35: Credit Card | P35: Cancelled | Q35: 45873 | R35: 4 | S35: =IF(B35<=Q35,"YES","NO") -> YES
A36: ORD1034 | B36: 45658 | C36: Michael Miller | D36: Kenya | E36: Nairobi | F36: Home & Kitchen | G36: HOME-2001-A-Air Fryer | H36: HOME | I36: =VLOOKUP(H36,REPORT!$B$1:$C$4,2,FALSE) -> Home & Kitchen | J36: =IF(F36=I36,"Match","Mismatch") -> Match | K36: 4 | L36: 220.65 | M36: 0.2 | N36: 706.08 | O36: PayPal | P36: Shipped | Q36: 45663 | R36: 5 | S36: =IF(B36<=Q36,"YES","NO") -> YES
A37: ORD1035 | B37: 45759 | C37: Daniel Davis | D37: Nigeria | E37: Lagos | F37: Beauty | G37: HOME-2001-A-Air Fryer | H37: HOME | I37: =VLOOKUP(H37,REPORT!$B$1:$C$4,2,FALSE) -> Home & Kitchen | J37: =IF(F37=I37,"Match","Mismatch") -> Mismatch | K37: 9 | L37: 335.29 | M37: 0.2 | N37: 2414.09 | O37: Credit Card | P37: Shipped | Q37: 45997 | R37: 3 | S37: =IF(B37<=Q37,"YES","NO") -> YES
A38: ORD1036 | B38: 45670 | C38: Sarah Wilson | D38: United Kingdom | E38: London | F38: Fashion | G38: ELEC-1002-Y-Bluetooth Speaker | H38: ELEC | I38: =VLOOKUP(H38,REPORT!$B$1:$C$4,2,FALSE) -> Electronics | J38: =IF(F38=I38,"Match","Mismatch") -> Mismatch | K38: -2 | L38: 309.52 | M38: 0 | N38: -619.04 | O38: Credit Card | P38: Shipped | Q38: 45671 | R38: 4 | S38: =IF(B38<=Q38,"YES","NO") -> YES
A39: ORD1037 | B39: 45733 | C39: Fatima Miller | D39: United Kingdom | E39: London | F39: Fashion | G39: ELEC-1001-X-Wireless Mouse | H39: ELEC | I39: =VLOOKUP(H39,REPORT!$B$1:$C$4,2,FALSE) -> Electronics | J39: =IF(F39=I39,"Match","Mismatch") -> Mismatch | K39: 2 | L39: 391.43 | M39: 0.05 | N39: 743.72 | O39: Credit Card | P39: Delivered | Q39: 45744 | R39: 2 | S39: =IF(B39<=Q39,"YES","NO") -> YES
A40: ORD1038 | B40: 45929 | C40: David Davis | D40: United Kingdom | E40: London | F40: Fashion | G40: BEAU-4001-C-Face Serum | H40: BEAU | I40: =VLOOKUP(H40,REPORT!$B$1:$C$4,2,FALSE) -> Beauty | J40: =IF(F40=I40,"Match","Mismatch") -> Mismatch | K40: 6 | L40: 475.52 | M40: 0.15 | N40: 2425.15 | O40: PayPal | P40: Delivered | Q40: 45938 | R40: 5 | S40: =IF(B40<=Q40,"YES","NO") -> YES
A41: ORD1039 | B41: 45984 | C41: Fatima Garcia | D41: South Africa | E41: Cape Town | F41: Electronics | G41: BEAU-4001-C-Face Serum | H41: BEAU | I41: =VLOOKUP(H41,REPORT!$B$1:$C$4,2,FALSE) -> Beauty | J41: =IF(F41=I41,"Match","Mismatch") -> Mismatch | K41: 8 | L41: 317.11 | M41: 0.1 | N41: 2283.19 | O41: Credit Card | P41: Complete | Q41: 45989 | R41: 4 | S41: =IF(B41<=Q41,"YES","NO") -> YES
A42: ORD1040 | B42: 45728 | C42: Aisha Taylor | D42: Kenya | E42: Nairobi | F42: Electronics | G42: ELEC-1002-Y-Bluetooth Speaker | H42: ELEC | I42: =VLOOKUP(H42,REPORT!$B$1:$C$4,2,FALSE) -> Electronics | J42: =IF(F42=I42,"Match","Mismatch") -> Match | K42: 7 | L42: 350.04 | M42: 0.05 | N42: 2327.77 | O42: Bank Transfer | P42: Pending | Q42: 45731 | S42: =IF(B42<=Q42,"YES","NO") -> YES
A43: ORD1041 | B43: 45857 | C43: John Wilson | D43: Nigeria | E43: Lagos | F43: Electronics | G43: BEAU-4001-C-Face Serum | H43: BEAU | I43: =VLOOKUP(H43,REPORT!$B$1:$C$4,2,FALSE) -> Beauty | J43: =IF(F43=I43,"Match","Mismatch") -> Mismatch | K43: 1 | L43: 429.8 | M43: 0.2 | N43: 343.84 | O43: Credit Card | P43: Pending | Q43: 45870 | R43: 4 | S43: =IF(B43<=Q43,"YES","NO") -> YES
A44: ORD1042 | B44: 45788 | C44: Daniel Martin | D44: United Kingdom | E44: London | F44: Fashion | G44: FASH-3001-B-Running Shoes | H44: FASH | I44: =VLOOKUP(H44,REPORT!$B$1:$C$4,2,FALSE) -> Fashion | J44: =IF(F44=I44,"Match","Mismatch") -> Match | K44: 4 | L44: 143.74 | M44: 0.15 | N44: 488.72 | O44: Cash | P44: Pending | Q44: 45970 | R44: 1 | S44: =IF(B44<=Q44,"YES","NO") -> YES
A45: ORD1043 | B45: 45976 | C45: Sophia Davis | D45: Nigeria | E45: Abuja | F45: Beauty | G45: ELEC-1001-X-Wireless Mouse | H45: ELEC | I45: =VLOOKUP(H45,REPORT!$B$1:$C$4,2,FALSE) -> Electronics | J45: =IF(F45=I45,"Match","Mismatch") -> Mismatch | K45: 7 | L45: 300.03 | M45: 0 | N45: 2100.21 | O45: PayPal | P45: Delivered | Q45: 45985 | R45: 1 | S45: =IF(B45<=Q45,"YES","NO") -> YES
A46: ORD1044 | B46: 45766 | C46: Michael Miller | D46: United Kingdom | E46: London | F46: Beauty | G46: HOME-2001-A-Air Fryer | H46: HOME | I46: =VLOOKUP(H46,REPORT!$B$1:$C$4,2,FALSE) -> Home & Kitchen | J46: =IF(F46=I46,"Match","Mismatch") -> Mismatch | K46: 6 | L46: 383 | M46: 1.5 | N46: -1149 | O46: Credit Card | P46: Pending | Q46: 45774 | R46: 3 | S46: =IF(B46<=Q46,"YES","NO") -> YES
...

Sheet REPORT
B1: ELEC | C1: Electronics
B2: BEAU | C2: Beauty
B3: FASH | C3: Fashion
B4: HOME | C4: Home & Kitchen
